Workbook

Sheet Talimatlar
B2: BSH BAYİ - DİVA SATIŞ / KAMPANYA / HAKEDİŞ KONTROL SİSTEMİ
B4: AMAÇ
B5: Bu dosya; bayinin DİVA üzerinden yaptığı kampanya kodlu satışları, E2E portaldan alınan nakliye/montaj sonuçlarını ve BSH'nin bayiye kestiği hakediş faturası detayını tek noktada eşleştirerek, hakedişin doğru hesaplanıp doğru ödenip ödenmediğini otomatik olarak kontrol eder.
B7: İKİ FARKLI HAKEDİŞ KURALI (kaynak: aylık 'Perakende Uygulama Yazısı')
B8: Kural A - Stok Mutabakatlı Bayi: Hakediş, DİVA'da hemen teslim faturalandırıldığı anda ödenir. Buna karşılık 30.11 itibarıyla yıl içinde hakediş ödenen ürünlerin nakliye VEYA montaj tamamlanma ORANININ toplam hakedişe oranı en az %75 olmalıdır; altında kalırsa aradaki fark mahsuplaşılır. (Bkz. 'Yil Sonu Kontrolu' sekmesi) Kural B - Stok Mutabakatı Yapılmamış Bayi: Hakediş, DİVA hemen teslim faturası olsa dahi hemen ödenmez; nakliye verisi varsa nakliyenin tamamlanmasını takip eden ayda, nakliye verisi yoksa montajın tamamlanmasını takip eden ayda ödenir. Bu tamamlanma, kampanyanın 'Hakediş Son Tarihi'nden önce gerçekleşmiş olmalıdır; aksi halde hakediş RİSK olarak işaretlenir.
B10: HANGİ BAYİ HANGİ KURALA TABİ?
B11: 'Parametreler' sekmesinde tek bir alanla belirlenir: 'Stok Mutabakatı Yapıldı mı?'. Bu bilgiyi BSH saha/finans ekibinizden teyit edin. Bu alan tüm 'DİVA Satışları' sekmesindeki her satır için otomatik kural ataması yapar.
B13: VERİ AKIŞI VE SEKME SAHİPLİĞİ
B14: 'Kampanyalar' sekmesi YÖNETİCİ (BSH) tarafından doldurulur ve şifre ile korumalıdır; bayi bu sekmeyi görebilir ama değiştiremez. Aylık kampanya duyuru yazısı (PDF) BSH tarafından işlenip bu sekmeye satır olarak eklenir. 'DİVA Satışları' sekmesine bayi, DİVA'dan alınan 'Kampanya Kodlu Satış' raporunu (Şirket Kodu...Kategori, 35 sütun) olduğu gibi kopyalayıp A3 hücresinden başlayarak yapıştırır. 'E2E Nakliye Montaj' sekmesine bayi, E2E portaldan alınan raporu (MerkezKodu...PlatformName, 38 sütun) A3 hücresinden başlayarak yapıştırır. 'Hakedis Fatura Detay' sekmesine bayi, BSH'nin her ay gönderdiği hakediş detay raporunu ("...DETAY" sekmesi, 32 sütun) yapıştırır.
B16: EŞLEŞTİRME ANAHTARI
B17: Tüm kaynaklar 'DİVA Fatura No (26 ile başlayan) + Ürün Kodu' ikilisi ile eşleştirilir. 'Kontrol' sekmesi bu anahtarla otomatik birleştirme yapar ve nihai durumu üretir.
B19: HAKEDİŞ VERİSİNİ AY AY BİRİKTİRİN - ÇOK ÖNEMLİ
... B26: Sarı zemin + mavi yazı = elle doldurulacak/yapıştırılacak alan. Gri başlık = kaynak rapordan birebir gelen ham sütun. Mavi başlık = otomatik hesaplanan sütun, dokunmayın. Turuncu zemin = risk/uyuşmazlık uyarısı. 'DİVA Satışları', 'E2E Nakliye Montaj' ve 'Hakedis Fatura Detay' sekmelerinde, yapıştırdığınız verinin bittiği satırın hemen üstünde otomatik MAVİ bir çizgi belirir — bu çizgi 'veriniz buraya kadar, altı hâlâ boş' demektir; yeni veri eklerken bu çizginin altına doğru devam edin. 'Kontrol' ve 'Sorun Raporu' sekmelerinde GENEL DURUM/SORUN hücreleri otomatik renklenir: YEŞİL = Uygun, KIRMIZI = İnceleme Gerekli, SARI = Bekleniyor.

Sheet Parametreler
B2: PARAMETRELER
B4: Bayi Kodu | C4: 7000129546
B5: Bayi Adı | C5: MUSTAFA DEMİREL
B7: Bu bayi için STOK MUTABAKATI yapıldı mı? (Evet = Kural A: hakediş DİVA çıkışında hemen ödenir. Hayır = Kural B: hakediş nakliye/montaj tamamlandıktan sonraki ay ödenir.) | C7: Evet
B9: Yıl Sonu Nakliye/Montaj Oranı Kontrol Tarihi (Kural A bayileri için) | C9: 30.11.2026
B10: Minimum Nakliye/Montaj Oranı Eşiği (Kural A) | C10: 0.75
B12: Not: 'Stok Mutabakatı' durumunu ve oranları BSH saha/finans ekibinizden teyit edin. Değer değiştiğinde tüm 'DİVA Satışları' ve 'Kontrol' sekmeleri otomatik olarak yeniden hesaplanır.

Sheet Kampanyalar
A1: Kampanya Adı (DİVA 'Paket Adı' ile BİREBİR aynı olmalı) | B1: Dönem (AAYYYY) | C1: Kampanya Tipi | D1: Ürün Grubu / Kapsam | E1: Kampanya Başlangıç | F1: Kampanya Bitiş | G1: Hakediş Son Tarihi | H1: Bayiye Ödenecek Sabit Hakediş Tutarı (TL) (boşsa DİVA indirimi esas alınır) | I1: Adet Limiti | J1: Diğer Kampanyalarla Birleşebilir mi | K1: Kaynak / Not
A2: Aralık Ankastre Set Alana 6000 TL İndirim-202512 | B2: 202512 | C2: Bundle-Set | D2: Ankastre Set (Fırın+Ocak+Davlumbaz) | E2: 04.12.2025 | F2: 31.12.2025 | G2: 31.05.2026 | H2: 4500 | I2: 2500 | J2: Tekil Evet / Bundle Hayır | K2: Kaynak: Aralık 2025 Perakende Uygulama Yazısı. PDF notu: Tüm set ürünleri aynı Diva faturasında olmalı
A3: Aralık Ankastre Set Alana 8000 TL İndirim-202512 | B3: 202512 | C3: Bundle-Set | D3: Ankastre Set (Fırın+Ocak+Davlumbaz) | E3: 04.12.2025 | F3: 31.12.2025 | G3: 31.05.2026 | H3: 6200 | I3: 2500 | J3: Tekil Evet / Bundle Hayır | K3: Kaynak: Aralık 2025 Perakende Uygulama Yazısı. PDF notu: Tüm set ürünleri aynı Diva faturasında olmalı
A4: Aralık Ayı Fırsat Ürünleri Kampanyası-202512 | B4: 202512 | C4: Diğer | D4: Çeşitli (Buzdolabı/Derin Dondurucu/Bulaşık Mak./Çamaşır Mak./Ankastre Fırın - hareketi düşük/2 yıl önce satışa kapanan modeller) | E4: 04.12.2025 | F4: 31.12.2025 | G4: 30.01.2026 | K4: Kaynak: Aralık 2025 Perakende Uygulama Yazısı. PDF notu: Fiyat farkı yöntemi: Montaj/Nakliye Adedi, sabit TL yok; hakediş son tarihi diğer kampanyalardan farklı (30.01.2026); Fiyat farkı yöntemi: Montaj/Nakliye Adedi, sabit TL yok; hakediş son tarihi diğer kampanyalardan farklı (31.01.2026)
A5: Aralık Kurutma+Bulaşık Alımına 10000 TL İndirim-202512 | B5: 202512 | C5: Bundle-Set | D5: Kurutma Makinesi + Seçili Beyaz Eşya (Buzdolabı/Çamaşır/Bulaşık/Derin Dondurucu) | E5: 04.12.2025 | F5: 31.12.2025 | G5: 31.05.2026 | H5: 8000 | I5: 3000 | J5: Tekil Evet / Bundle Hayır | K5: Kaynak: Aralık 2025 Perakende Uygulama Yazısı. PDF notu: Kampanya birleşme kısıtı: sadece tekil ile birleşir
A6: Aralık Soğutucu + Bulaşık Alımına 5000 TL İndirim-202512 | B6: 202512 | C6: Bundle-Set | D6: Beyaz Eşya 2'li Set (Buzdolabı/Çamaşır Mak./Bulaşık Mak./Derin Dondurucu) | E6: 04.12.2025 | F6: 31.12.2025 | G6: 31.05.2026 | H6: 3900 | I6: 3000 | J6: Tekil Evet / Bundle Hayır | K6: Kaynak: Aralık 2025 Perakende Uygulama Yazısı. PDF notu: Kampanya birleşme kısıtı: sadece tekil ile birleşir; Kampanya birleşme kısıtı: sadece tekil kampanyalar ile birleşir, diğer bundle kampanyalarla birleşmez
A7: Aralık Tekil Bulaşık Makinesi Kampanyası-202512 | B7: 202512 | C7: Tekil | D7: Bulaşık Makinesi | E7: 04.12.2025 | F7: 31.12.2025 | G7: 31.05.2026 | J7: Evet | K7: Kaynak: Aralık 2025 Perakende Uygulama Yazısı. PDF notu: Fiyat farkı yöntemi: Montaj/Nakliye Adedi, sabit TL tutarı belirtilmemiş
A8: Aralık Tekil Kurutma Makinesi Kampanyası-202512 | B8: 202512 | C8: Tekil | D8: Kurutma Makinesi | E8: 04.12.2025 | F8: 31.12.2025 | G8: 31.05.2026 | J8: Evet | K8: Kaynak: Aralık 2025 Perakende Uygulama Yazısı. PDF notu: 30 gün koşulsuz iade uygulaması + fiyat farkı yöntemi Montaj/Nakliye Adedi, sabit TL yok
A9: Aralık Tekil Soğutucu Kampanyası-202512 | B9: 202512 | C9: Tekil | D9: Soğutucu | E9: 04.12.2025 | F9: 31.12.2025 | G9: 31.05.2026 | J9: Evet | K9: Kaynak: Aralık 2025 Perakende Uygulama Yazısı. PDF notu: Fiyat farkı yöntemi: Montaj/Nakliye Adedi, sabit TL tutarı belirtilmemiş; Fiyat farkı yöntemi: Montaj/Nakliye Adedi, sabit TL tutarı belirtilmemiş; model listesi ile sınırlı
A10: Aralık Tekil Çamaşır Kampanyası-202512 | B10: 202512 | C10: Tekil | D10: Çamaşır Makinesi | E10: 04.12.2025 | F10: 31.12.2025 | G10: 31.05.2026 | J10: Evet | K10: Kaynak: Aralık 2025 Perakende Uygulama Yazısı. PDF notu: Fiyat farkı yöntemi: Montaj/Nakliye Adedi, sabit TL tutarı belirtilmemiş
A11: Aralık-Aile Bakanlığı Kampanyası – Bosch-202512 | B11: 202512 | C11: Diğer | D11: Çeşitli (Buzdolabı/Derin Dondurucu/Çamaşır/Kurutma/Bulaşık/Fırın/Mikrodalga/Ocak/Davlumbaz/Küçük Ev Aletleri) | E11: 04.12.2025 | F11: 31.12.2025 | G11: 31.05.2026 | K11: DİVA Paket Adı ORNEK SATIS VERISINDE TEYIT EDILEMEDI (o ay bu kampanyadan satis olmamis olabilir) - Kampanya Adi sutunu DIVA'daki gercek Paket Adi ile ADMIN tarafindan TEYIT EDILMELI. PDF notu: TRPF üzerinden ekstra %5 indirim (sabit TL değil); KEA modellerinde hakediş son tarihi 31.12.2025, diğer ürünlerde 31.05.2026; Tüketiciye TRPF üzerinden ekstra %5 indirim (sabit TL değil), Aile Bakanlığı evlilik kredisi indirim kodu ile; KEA (Küçük Ev Aletleri) modellerinde hakediş son tarihi 15.12.
A12: Aralık-Ankastre Set Fırsat 3: Seçili Ankastre Set ile Birlikte Ankastre Bulaşık Makinesi Alan Tüketicilerimize 12.000 TL İndirim-202512 | B12: 202512 | C12: Bundle-Set | D12: Ankastre Set (Fırın+Ocak+Davlumbaz) + Ankastre Bulaşık Makinesi | E12: 04.12.2025 | F12: 31.12.2025 | G12: 31.05.2026 | H12: 12000 | I12: 300 | J12: Tekil Evet / Bundle Hayır | K12: DİVA Paket Adı ORNEK SATIS VERISINDE TEYIT EDILEMEDI (o ay bu kampanyadan satis olmamis olabilir) - Kampanya Adi sutunu DIVA'daki gercek Paket Adi ile ADMIN tarafindan TEYIT EDILMELI. PDF notu: Tüm set ürünleri (fırın, ocak, davlumbaz, bulaşık makinesi) aynı Diva faturasında olmalı; Tüm set ürünleri aynı Diva faturasında olmalı
A13: Aralık-Bosch Premium Seçili Büyük Beyaz Eşya Seti - Seçili modelleden (Buzdolabı, Çamaşır Makinesi, Kurutma Makinesi, Bulaşık Makinesi ve Ankastre Fırın) Üçlü Beyaz Eşya Seti Alana BCS1041WAC Unlimited Süpürge Hediye-202512 | B13: 202512 | C13: Küçük Ev Aletleri | D13: Büyük Beyaz Eşya 3'lü Set (Buzdolabı/Çamaşır/Kurutma/Bulaşık/Ankastre Fırın) | E13: 04.12.2025 | F13: 31.12.2025 | G13: 31.05.2026 | H13: 25000 | I13: 100 | K13: DİVA Paket Adı ORNEK SATIS VERISINDE TEYIT EDILEMEDI (o ay bu kampanyadan satis olmamis olabilir) - Kampanya Adi sutunu DIVA'daki gercek Paket Adi ile ADMIN tarafindan TEYIT EDILMELI. PDF notu: Hediye ürün BCS1041WAC alımı zorunlu; Hediye ürün BCS1041WAC alımı zorunlu, alınmazsa kampanya kapsamı dışı kalır; tüketiciye TL indirimi değil hediye ürün verilir
A14: Aralık-Derin Dondurucu Kampanyası-202512 | B14: 202512 | C14: Bundle-Set | D14: Derin Dondurucu | E14: 04.12.2025 | F14: 31.12.2025 | G14: 31.05.2026 | J14: Tekil Evet / Bundle Hayır | K14: DİVA Paket Adı ORNEK SATIS VERISINDE TEYIT EDILEMEDI (o ay bu kampanyadan satis olmamis olabilir) - Kampanya Adi sutunu DIVA'daki gercek Paket Adi ile ADMIN tarafindan TEYIT EDILMELI. PDF notu: Fiyat farkı yöntemi: Montaj/Nakliye Adedi, sabit TL tutarı belirtilmemiş
A15: Aralık-Süpürge Değişim Kampanyası (Eskiyi Getir, Yeniyi Götür)-202512 | B15: 202512 | C15: Küçük Ev Aletleri | D15: Süpürge | E15: 04.12.2025 | F15: 31.12.2025 | G15: 31.12.2025 | I15: 1250 | K15: DİVA Paket Adı ORNEK SATIS VERISINDE TEYIT EDILEMEDI (o ay bu kampanyadan satis olmamis olabilir) - Kampanya Adi sutunu DIVA'daki gercek Paket Adi ile ADMIN tarafindan TEYIT EDILMELI. PDF notu: Değişim/trade-in kampanyası; hakediş tutarı belirtilmemiş, sadece yeni TRPF listesi verilmiş; eski süpürgenin kargo ile BSH İade Depo'ya gönderilmesi şart; hakediş için sabit tutar yok, hemen teslim satışı zorunlu (ileri teslim kapsam dışı); Değişim/trade-in kampanyası; hakediş tutarı belirtilmemiş,
A16: Aralık-Tekil Ankastre Kampanyası-202512 | B16: 202512 | C16: Tekil | D16: Ankastre (Fırın hariç Ocak/Davlumbaz) | E16: 04.12.2025 | F16: 31.12.2025 | G16: 31.05.2026 | J16: Evet | K16: DİVA Paket Adı ORNEK SATIS VERISINDE TEYIT EDILEMEDI (o ay bu kampanyadan satis olmamis olabilir) - Kampanya Adi sutunu DIVA'daki gercek Paket Adi ile ADMIN tarafindan TEYIT EDILMELI. PDF notu: Fiyat farkı yöntemi: Montaj/Nakliye Adedi, sabit TL tutarı belirtilmemiş
A17: Ocak-Ankastre Set Alana 6000 TL İndirim-202601 | B17: 202601 | C17: Bundle-Set | D17: Ankastre Set (Fırın+Ocak+Davlumbaz) | E17: 07.01.2026 | F17: 31.01.2026 | G17: 31.05.2026 | H17: 4500 | I17: 2500 | J17: Tekil Evet / Bundle Hayır | K17: Kaynak: Ocak 2026 Perakende Uygulama Yazısı. PDF notu: Tüm set ürünleri aynı Diva faturasında olmalı
A18: Ocak-Soğutucu+Kurutma Alımına 10000 TL İndirim-202601 | B18: 202601 | C18: Bundle-Set | D18: Kurutma Makinesi + Seçili Beyaz Eşya (Buzdolabı/Çamaşır/Bulaşık/Derin Dondurucu) | E18: 07.01.2026 | F18: 31.01.2026 | G18: 31.05.2026 | H18: 8000 | I18: 3000 | J18: Tekil Evet / Bundle Hayır | K18: Kaynak: Ocak 2026 Perakende Uygulama Yazısı. PDF notu: Kampanya birleşme kısıtı: sadece tekil ile birleşir
A19: Ocak-Tekil Bulaşık Makinesi Kampanyası-202601 | B19: 202601 | C19: Tekil | D19: Bulaşık Makinesi | E19: 07.01.2026 | F19: 31.01.2026 | G19: 31.05.2026 | J19: Evet | K19: Kaynak: Ocak 2026 Perakende Uygulama Yazısı. PDF notu: Fiyat farkı yöntemi: Montaj/Nakliye Adedi, sabit TL tutarı belirtilmemiş; Fiyat farkı yöntemi: Montaj/Nakliye Adedi, sabit TL yok; stok mutabakatı %75 kuralı (30.11.2026) geçerli
A20: Ocak-Tekil Kurutma Makinesi Kampanyası-202601 | B20: 202601 | C20: Tekil | D20: Kurutma Makinesi | E20: 07.01.2026 | F20: 31.01.2026 | G20: 31.05.2026 | J20: Evet | K20: Kaynak: Ocak 2026 Perakende Uygulama Yazısı. PDF notu: 30 gün koşulsuz iade + fiyat farkı yöntemi Montaj/Nakliye Adedi, sabit TL yok; stok mutabakatı %75 kuralı geçerli; 30 gün koşulsuz iade uygulaması + fiyat farkı yöntemi Montaj/Nakliye Adedi, sabit TL yok
A21: Ocak-Tekil Soğutucu Kampanyası-202601 | B21: 202601 | C21: Tekil | D21: Soğutucu | E21: 07.01.2026 | F21: 31.01.2026 | G21: 31.05.2026 | J21: Evet | K21: Kaynak: Ocak 2026 Perakende Uygulama Yazısı. PDF notu: Fiyat farkı yöntemi: Montaj/Nakliye Adedi, sabit TL tutarı belirtilmemiş; Fiyat farkı yöntemi: Montaj/Nakliye Adedi, sabit TL yok. Bu aydan itibaren stok mutabakatı yapılmış bayilerde 30.11.2026 itibariyle nakliye/montaj oranı toplam hakedişin min. %75'i olmalı, altındaysa fark mahsuplaşılır
A22: Ocak-Tekil Çamaşır Kampanyası-202601 | B22: 202601 | C22: Tekil | D22: Çamaşır Makinesi | E22: 07.01.2026 | F22: 31.01.2026 | G22: 31.05.2026 | J22: Evet | K22: Kaynak: Ocak 2026 Perakende Uygulama Yazısı. PDF notu: Fiyat farkı yöntemi: Montaj/Nakliye Adedi, sabit TL tutarı belirtilmemiş; Fiyat farkı yöntemi: Montaj/Nakliye Adedi, sabit TL yok; stok mutabakatı %75 kuralı (30.11.2026) geçerli
A23: Ocak-Aile Bakanlığı Kampanyası – Bosch-202601 | B23: 202601 | C23: Diğer | D23: Çeşitli (Buzdolabı/Derin Dondurucu/Çamaşır/Kurutma/Bulaşık/Fırın/Mikrodalga/Ocak/Davlumbaz/Küçük Ev Aletleri) | E23: 07.01.2026 | F23: 31.01.2026 | G23: 31.05.2026 | K23: DİVA Paket Adı ORNEK SATIS VERISINDE TEYIT EDILEMEDI (o ay bu kampanyadan satis olmamis olabilir) - Kampanya Adi sutunu DIVA'daki gercek Paket Adi ile ADMIN tarafindan TEYIT EDILMELI. PDF notu: TRPF üzerinden ekstra %5 indirim (sabit TL değil); KEA modellerinde hakediş son tarihi 15.01.2026, diğer ürünlerde 31.05.2026; TRPF üzerinden ekstra %5 indirim (sabit TL değil); KEA modellerinde hakediş son tarihi 31.01.2026, diğer ürünlerde 31.05.2026
A24: Ocak-Ankastre Set Fırsat 2: Seçili Ankastre Set Alan Tüketicilerimize 8.000 TL İndirim-202601 | B24: 202601 | C24: Bundle-Set | D24: Ankastre Set (Fırın+Ocak+Davlumbaz) | E24: 07.01.2026 | F24: 31.01.2026 | G24: 31.05.2026 | H24: 6200 | I24: 2500 | J24: Tekil Evet / Bundle Hayır | K24: DİVA Paket Adı ORNEK SATIS VERISINDE TEYIT EDILEMEDI (o ay bu kampanyadan satis olmamis olabilir) - Kampanya Adi sutunu DIVA'daki gercek Paket Adi ile ADMIN tarafindan TEYIT EDILMELI. PDF notu: Tüm set ürünleri aynı Diva faturasında olmalı
A25: Ocak-Ankastre Set Fırsat 3: Seçili Ankastre Set ile Birlikte Ankastre Bulaşık Makinesi Alan Tüketicilerimize 12.000 TL İndirim-202601 | B25: 202601 | C25: Bundle-Set | D25: Ankastre Set (Fırın+Ocak+Davlumbaz) + Ankastre Bulaşık Makinesi | E25: 07.01.2026 | F25: 31.01.2026 | G25: 31.05.2026 | H25: 12000 | I25: 300 | J25: Tekil Evet / Bundle Hayır | K25: DİVA Paket Adı ORNEK SATIS VERISINDE TEYIT EDILEMEDI (o ay bu kampanyadan satis olmamis olabilir) - Kampanya Adi sutunu DIVA'daki gercek Paket Adi ile ADMIN tarafindan TEYIT EDILMELI. PDF notu: Tüm set ürünleri aynı Diva faturasında olmalı
A26: Ocak-Bosch Premium Seçili Büyük Beyaz Eşya Seti - Seçili modelleden (Buzdolabı, Çamaşır Makinesi, Kurutma Makinesi, Bulaşık Makinesi) 4'lü Beyaz Eşya Seti Alana BCS1041WAC Unlimited Süpürge Hediye-202601 | B26: 202601 | C26: Küçük Ev Aletleri | D26: Büyük Beyaz Eşya 4'lü Set (Buzdolabı/Çamaşır/Kurutma/Bulaşık) | E26: 07.01.2026 | F26: 31.01.2026 | G26: 31.05.2026 | H26: 27000 | I26: 100 | K26: DİVA Paket Adı ORNEK SATIS VERISINDE TEYIT EDILEMEDI (o ay bu kampanyadan satis olmamis olabilir) - Kampanya Adi sutunu DIVA'daki gercek Paket Adi ile ADMIN tarafindan TEYIT EDILMELI. PDF notu: Hediye alınmazsa 34.000 TL indirim uygulanır; Hediye alınmazsa 34.000 TL indirim uygulanır (Ankastre Fırın bu ay set kapsamı dışı, önceki aydan farklı)
A27: Ocak-Derin Dondurucu Kampanyası-202601 | B27: 202601 | C27: Bundle-Set | D27: Derin Dondurucu | E27: 20.01.2026 | F27: 31.01.2026 | G27: 31.05.2026 | J27: Tekil Evet / Bundle Hayır | K27: DİVA Paket Adı ORNEK SATIS VERISINDE TEYIT EDILEMEDI (o ay bu kampanyadan satis olmamis olabilir) - Kampanya Adi sutunu DIVA'daki gercek Paket Adi ile ADMIN tarafindan TEYIT EDILMELI. PDF notu: Fiyat farkı yöntemi: Montaj/Nakliye Adedi, sabit TL yok; model tablosu tekrar mevcut (önceki PDF'te yoktu)
A28: Ocak-Ocak Ayı Bulaşık Makineli Çeyiz Seti - 3 Büyük Beyaz Eşya (Buzdolabı, Çamaşır Makinesi, Kurutma Makinesi, Derin Dondurucu) ile Birlikte SMS26DW00T Bulaşık Makinesi Alımına Hediye Edilecektir-202601 | B28: 202601 | C28: Bundle-Set | D28: Büyük Beyaz Eşya 3'lü Set + Bulaşık Makinesi | E28: 07.01.2026 | F28: 31.01.2026 | G28: 31.05.2026 | H28: 17900 | I28: 2000 | J28: Tekil Evet / Bundle Hayır | K28: DİVA Paket Adı ORNEK SATIS VERISINDE TEYIT EDILEMEDI (o ay bu kampanyadan satis olmamis olabilir) - Kampanya Adi sutunu DIVA'daki gercek Paket Adi ile ADMIN tarafindan TEYIT EDILMELI. PDF notu: SMS26DW00T hediye edilir; farklı bulaşık makinesi tercih edilirse 22.000 TL indirim uygulanır; tekil ile birleşir, bundle ile birleşmez
A29: Ocak-Ocak Ayı Fırsat Ürünleri Kampanyası-202601 | B29: 202601 | C29: Diğer | D29: Çeşitli (Buzdolabı/Derin Dondurucu/Bulaşık Mak./Çamaşır Mak./Ankastre Fırın - hareketi düşük modeller) | E29: 07.01.2026 | F29: 31.01.2026 | G29: 28.02.2026 | K29: DİVA Paket Adı ORNEK SATIS VERISINDE TEYIT EDILEMEDI (o ay bu kampanyadan satis olmamis olabilir) - Kampanya Adi sutunu DIVA'daki gercek Paket Adi ile ADMIN tarafindan TEYIT EDILMELI. PDF notu: Fiyat farkı yöntemi: Montaj/Nakliye Adedi, sabit TL yok; hakediş son tarihi diğer kampanyalardan farklı (28.02.2026)
A30: Ocak-Tekil Ankastre Kampanyası-202601 | B30: 202601 | C30: Tekil | D30: Ankastre (Fırın hariç Ocak/Davlumbaz) | E30: 07.01.2026 | F30: 31.01.2026 | G30: 31.05.2026 | J30: Evet | K30: DİVA Paket Adı ORNEK SATIS VERISINDE TEYIT EDILEMEDI (o ay bu kampanyadan satis olmamis olabilir) - Kampanya Adi sutunu DIVA'daki gercek Paket Adi ile ADMIN tarafindan TEYIT EDILMELI. PDF notu: Fiyat farkı yöntemi: Montaj/Nakliye Adedi, sabit TL tutarı belirtilmemiş
A31: Şubat Ayı Fırsat Ürünleri Kampanyası-202602 | B31: 202602 | C31: Diğer | D31: Çeşitli (Buzdolabı/Derin Dondurucu/Bulaşık Mak./Çamaşır Mak./Ankastre Fırın - hareketi düşük modeller) | E31: 04.02.2026 | F31: 28.02.2026 | G31: 31.03.2026 | K31: Kaynak: Şubat 2026 Perakende Uygulama Yazısı. PDF notu: Fiyat farkı yöntemi: Montaj/Nakliye Adedi, sabit TL yok; hakediş son tarihi diğer kampanyalardan farklı (31.03.2026); Hareket hızı düşük/2 yıl önce satışa kapanan modeller; hakediş son tarihi diğerlerinden farklı olarak 31.03.2026
A32: Şubat XL/XXL Soğutucu-RDW1276 Su Sebili Kampanyası-202602 | B32: 202602 | C32: Bundle-Set | D32: Buzdolabı (XL/XXL) | E32: 04.02.2026 | F32: 28.02.2026 | G32: 30.11.2026 | H32: 7200 | I32: 2500 | J32: Tekil Evet / Bundle Hayır | K32: Kaynak: Şubat 2026 Perakende Uygulama Yazısı. PDF notu: RDW1276 su sebili hediye; alınmazsa 9.700 TL indirim; Yeni kampanya (önceki 4 PDF'te yoktu); hediye RDW1276 su sebili alınmazsa 9.700 TL indirim uygulanır; tekil ile birleşir, bundle ile birleşmez
A33: Şubat-Ankastre Set Alana 6000 TL İndirim-202602 | B33: 202602 | C33: Bundle-Set | D33: Ankastre Set (Fırın+Ocak+Davlumbaz) | E33: 04.02.2026 | F33: 28.02.2026 | G33: 30.11.2026 | H33: 4500 | I33: 2500 | J33: Tekil Evet / Bundle Hayır | K33: Kaynak: Şubat 2026 Perakende Uygulama Yazısı. PDF notu: Tüm set ürünleri aynı Diva faturasında olmalı; ankastre fırın model listesi daralmış (HUA717 serisi bu kampanyadan çıkmış)
A34: Şubat-Bulaşık Makineli Çeyiz Seti 2-202602 | B34: 202602 | C34: Bundle-Set | D34: 3'lü Büyük Beyaz Eşya + Bulaşık Makinesi | E34: 17.02.2026 | F34: 28.02.2026 | G34: 30.11.2026 | H34: 8000 | I34: 3000 | J34: Tekil Evet / Bundle Hayır | K34: Kaynak: Şubat 2026 Perakende Uygulama Yazısı. DİKKAT: Ay içindeki iki uygulama yazısı arasında tutar farkı görüldü (tüketici indirimleri: [10000, 23090], bayi hakedişleri: [8000, 17900]); en güncel (son yarı) değer alındı, admin teyit etmeli. PDF notu: En az 3 büyük beyaz eşya + SMS26DW00T bulaşık makinesi alımına hediye/indirim; Metinde 'Şubat Ayı Kurutmalı 2'li Beyaz Eşya Fırsatı' olarak da anılıyor
A35: Şubat-Bulaşık Makineli Çeyiz Seti 4-202602 | B35: 202602 | C35: Bundle-Set | D35: Büyük Beyaz Eşya 4'lü Set (Buzdolabı/Çamaşır/Kurutma/Bulaşık) | E35: 04.02.2026 | F35: 15.02.2026 | G35: 30.11.2026 | H35: 27000 | I35: 100 | J35: Tekil Evet / Bundle Hayır | K35: Kaynak: Şubat 2026 Perakende Uygulama Yazısı. PDF notu: Hediye alınmazsa 35.450 TL indirim uygulanır (önceki ayda 34.000 TL idi)
A36: Şubat-Tekil Bulaşık Makinesi Kampanyası-202602 | B36: 202602 | C36: Tekil | D36: Bulaşık Makinesi | E36: 04.02.2026 | F36: 28.02.2026 | G36: 30.11.2026 | J36: Evet | K36: Kaynak: Şubat 2026 Perakende Uygulama Yazısı. PDF notu: Fiyat farkı yöntemi: Montaj/Nakliye Adedi, sabit TL yok; stok mutabakatı %75 kuralı (30.11.2026) geçerli
A37: Şubat-Tekil Derin Dondurucu Kampanyası-202602 | B37: 202602 | C37: Tekil | D37: Derin Dondurucu | E37: 04.02.2026 | F37: 28.02.2026 | G37: 30.11.2026 | J37: Evet | K37: Kaynak: Şubat 2026 Perakende Uygulama Yazısı. PDF notu: Fiyat farkı yöntemi: Montaj/Nakliye Adedi, sabit TL yok
A38: Şubat-Tekil Kurutma Makinesi Kampanyası-202602 | B38: 202602 | C38: Tekil | D38: Kurutma Makinesi | E38: 04.02.2026 | F38: 28.02.2026 | G38: 30.11.2026 | J38: Evet | K38: Kaynak: Şubat 2026 Perakende Uygulama Yazısı. PDF notu: 30 gün koşulsuz iade + fiyat farkı yöntemi Montaj/Nakliye Adedi, sabit TL yok; stok mutabakatı %75 kuralı geçerli; 30 gün koşulsuz iade uygulaması da mevcut
A39: Şubat-Tekil Soğutucu Kampanyası-202602 | B39: 202602 | C39: Tekil | D39: Soğutucu | E39: 04.02.2026 | F39: 28.02.2026 | G39: 30.11.2026 | J39: Evet | K39: Kaynak: Şubat 2026 Perakende Uygulama Yazısı. PDF notu: Fiyat farkı Montaj/Nakliye Adedi yöntemiyle hesaplanır, sabit TL belirtilmemiş; Fiyat farkı yöntemi: Montaj/Nakliye Adedi, sabit TL yok; hakediş invoicing/montaj penceresi bu ay itibariyle 30.11.2026'ya uzatıldı; stok mutabakatı %75 kuralı (30.11.2026) geçerli
A40: Şubat-Tekil Çamaşır Kampanyası-202602 | B40: 202602 | C40: Tekil | D40: Çamaşır Makinesi | E40: 04.02.2026 | F40: 28.02.2026 | G40: 30.11.2026 | J40: Evet | K40: Kaynak: Şubat 2026 Perakende Uygulama Yazısı. PDF notu: Fiyat farkı yöntemi: Montaj/Nakliye Adedi, sabit TL yok; stok mutabakatı %75 kuralı (30.11.2026) geçerli
...

Sheet DIVA Satislari
A1: Şirket Kodu | B1: Şirket Adı | C1: Şube Kodu | D1: Şube Adı | E1: Bayi Kodu | F1: Aile | G1: Firma Adı | H1: Fatura Tarihi | I1: Fatura No | J1: Sipariş No | K1: Müşteri Kart No | L1: Hesap Kodu | M1: Ad Soyad | N1: Kampanya Tipi | O1: Paket Adı | P1: Satır İndirim Tipi | Q1: Dip İndirim Tipi | R1: Ürün Kodu | S1: Ürün Adı | T1: Barkod | U1: Miktar | V1: Kazanılan Kod | W1: Kullanılan Kod | X1: Seri No | Y1: Brüt | Z1: Satır İndirimi | AA1: İndirim (%) | AB1: Dip İndirim | AC1: İndirim (%)1 | AD1: Toplam İndirim | AE1: İndirim (%)2 | AF1: Fatura Tutarı | AG1: KDV Tutarı | AH1: Özel Kod 2 | AI1: Kategori | AJ1: Eşleştirme Anahtarı (Ürün Düzeyi - FaturaNo+Ürün) | AK1: Eşleştirme Anahtarı (Kampanya Düzeyi - FaturaNo+Ürün+Kampanya) | AL1: Kampanya Bulundu mu | AM1: Kampanya Başlangıç | AN1: Kampanya Bitiş | AO1: Hakediş Son Tarihi | AP1: Fatura Tarihi Kampanya Aralığında mı | AQ1: Sabit Hakediş Tutarı (varsa) | AR1: Beklenen Hakediş Tutarı | AS1: Uygulanacak Kural (Ön Beklenti)
A2: BSHMDEMIR | B2: MUSTAFA DEMİREL | C2: BSHMDEMIR | D2: MUSTAFA DEMİREL | E2: 7000129546 | F2: Bosch-LDA | H2: 24.08.2026 | I2: 2600000650 | L2: X000002267 | M2: ÖRNEK MÜŞTERİ | N2: Fatura altı indirim | O2: Ağustos-Tekil Bulaşık Makinesi Kampanyası-202608 | R2: SMS4IKW62T | S2: Solo bulaşık makinesi | T2: 4242005342716 | U2: 1 | Y2: 37000 | Z2: 5761.9 | AA2: 15.57 | AB2: 0 | AC2: 0 | AD2: 5761.9 | AE2: 15.6 | AF2: 31238.1 | AG2: 5206.35
AJ3: =IF(I3="","",I3&"|"&R3) | AK3: =IF(I3="","",I3&"|"&R3&"|"&O3) | AL3: =IF(I3="","",IF(ISNA(MATCH(O3,Kampanyalar!$A$2:$A$400,0)),"Hayır - Kampanyalar'da Yok","Evet")) | AM3: =IF(I3="","",IFERROR(INDEX(Kampanyalar!$E$2:$E$400,MATCH(O3,Kampanyalar!$A$2:$A$400,0)),"")) | AN3: =IF(I3="","",IFERROR(INDEX(Kampanyalar!$F$2:$F$400,MATCH(O3,Kampanyalar!$A$2:$A$400,0)),"")) | AO3: =IF(I3="","",IFERROR(INDEX(Kampanyalar!$G$2:$G$400,MATCH(O3,Kampanyalar!$A$2:$A$400,0)),"")) | AP3: =IF(OR(I3="",AM3="",AN3=""),"",IF(AND(H3>=AM3,H3<=AN3),"Evet","HAYIR - Tarih Dışı")) | AQ3: =IF(I3="","",IFERROR(INDEX(Kampanyalar!$H$2:$H$400,MATCH(O3,Kampanyalar!$A$2:$A$400,0)),"")) | AR3: =IF(I3="","",IF(ISNUMBER(AQ3),AQ3,AD3)) | AS3: =IF(I3="","",IF(Parametreler!$C$7="Evet","Kural A - Hemen Ödeme (Stok Mutabakatlı)","Kural B - Nakliye/Montaj Sonrası Ödeme"))
AJ4: =IF(I4="","",I4&"|"&R4) | AK4: =IF(I4="","",I4&"|"&R4&"|"&O4) | AL4: =IF(I4="","",IF(ISNA(MATCH(O4,Kampanyalar!$A$2:$A$400,0)),"Hayır - Kampanyalar'da Yok","Evet")) | AM4: =IF(I4="","",IFERROR(INDEX(Kampanyalar!$E$2:$E$400,MATCH(O4,Kampanyalar!$A$2:$A$400,0)),"")) | AN4: =IF(I4="","",IFERROR(INDEX(Kampanyalar!$F$2:$F$400,MATCH(O4,Kampanyalar!$A$2:$A$400,0)),"")) | AO4: =IF(I4="","",IFERROR(INDEX(Kampanyalar!$G$2:$G$400,MATCH(O4,Kampanyalar!$A$2:$A$400,0)),"")) | AP4: =IF(OR(I4="",AM4="",AN4=""),"",IF(AND(H4>=AM4,H4<=AN4),"Evet","HAYIR - Tarih Dışı")) | AQ4: =IF(I4="","",IFERROR(INDEX(Kampanyalar!$H$2:$H$400,MATCH(O4,Kampanyalar!$A$2:$A$400,0)),"")) | AR4: =IF(I4="","",IF(ISNUMBER(AQ4),AQ4,AD4)) | AS4: =IF(I4="","",IF(Parametreler!$C$7="Evet","Kural A - Hemen Ödeme (Stok Mutabakatlı)","Kural B - Nakliye/Montaj Sonrası Ödeme"))
AJ5: =IF(I5="","",I5&"|"&R5) | AK5: =IF(I5="","",I5&"|"&R5&"|"&O5) | AL5: =IF(I5="","",IF(ISNA(MATCH(O5,Kampanyalar!$A$2:$A$400,0)),"Hayır - Kampanyalar'da Yok","Evet")) | AM5: =IF(I5="","",IFERROR(INDEX(Kampanyalar!$E$2:$E$400,MATCH(O5,Kampanyalar!$A$2:$A$400,0)),"")) | AN5: =IF(I5="","",IFERROR(INDEX(Kampanyalar!$F$2:$F$400,MATCH(O5,Kampanyalar!$A$2:$A$400,0)),"")) | AO5: =IF(I5="","",IFERROR(INDEX(Kampanyalar!$G$2:$G$400,MATCH(O5,Kampanyalar!$A$2:$A$400,0)),"")) | AP5: =IF(OR(I5="",AM5="",AN5=""),"",IF(AND(H5>=AM5,H5<=AN5),"Evet","HAYIR - Tarih Dışı")) | AQ5: =IF(I5="","",IFERROR(INDEX(Kampanyalar!$H$2:$H$400,MATCH(O5,Kampanyalar!$A$2:$A$400,0)),"")) | AR5: =IF(I5="","",IF(ISNUMBER(AQ5),AQ5,AD5)) | AS5: =IF(I5="","",IF(Parametreler!$C$7="Evet","Kural A - Hemen Ödeme (Stok Mutabakatlı)","Kural B - Nakliye/Montaj Sonrası Ödeme"))
AJ6: =IF(I6="","",I6&"|"&R6) | AK6: =IF(I6="","",I6&"|"&R6&"|"&O6) | AL6: =IF(I6="","",IF(ISNA(MATCH(O6,Kampanyalar!$A$2:$A$400,0)),"Hayır - Kampanyalar'da Yok","Evet")) | AM6: =IF(I6="","",IFERROR(INDEX(Kampanyalar!$E$2:$E$400,MATCH(O6,Kampanyalar!$A$2:$A$400,0)),"")) | AN6: =IF(I6="","",IFERROR(INDEX(Kampanyalar!$F$2:$F$400,MATCH(O6,Kampanyalar!$A$2:$A$400,0)),"")) | AO6: =IF(I6="","",IFERROR(INDEX(Kampanyalar!$G$2:$G$400,MATCH(O6,Kampanyalar!$A$2:$A$400,0)),"")) | AP6: =IF(OR(I6="",AM6="",AN6=""),"",IF(AND(H6>=AM6,H6<=AN6),"Evet","HAYIR - Tarih Dışı")) | AQ6: =IF(I6="","",IFERROR(INDEX(Kampanyalar!$H$2:$H$400,MATCH(O6,Kampanyalar!$A$2:$A$400,0)),"")) | AR6: =IF(I6="","",IF(ISNUMBER(AQ6),AQ6,AD6)) | AS6: =IF(I6="","",IF(Parametreler!$C$7="Evet","Kural A - Hemen Ödeme (Stok Mutabakatlı)","Kural B - Nakliye/Montaj Sonrası Ödeme"))
AJ7: =IF(I7="","",I7&"|"&R7) | AK7: =IF(I7="","",I7&"|"&R7&"|"&O7) | AL7: =IF(I7="","",IF(ISNA(MATCH(O7,Kampanyalar!$A$2:$A$400,0)),"Hayır - Kampanyalar'da Yok","Evet")) | AM7: =IF(I7="","",IFERROR(INDEX(Kampanyalar!$E$2:$E$400,MATCH(O7,Kampanyalar!$A$2:$A$400,0)),"")) | AN7: =IF(I7="","",IFERROR(INDEX(Kampanyalar!$F$2:$F$400,MATCH(O7,Kampanyalar!$A$2:$A$400,0)),"")) | AO7: =IF(I7="","",IFERROR(INDEX(Kampanyalar!$G$2:$G$400,MATCH(O7,Kampanyalar!$A$2:$A$400,0)),"")) | AP7: =IF(OR(I7="",AM7="",AN7=""),"",IF(AND(H7>=AM7,H7<=AN7),"Evet","HAYIR - Tarih Dışı")) | AQ7: =IF(I7="","",IFERROR(INDEX(Kampanyalar!$H$2:$H$400,MATCH(O7,Kampanyalar!$A$2:$A$400,0)),"")) | AR7: =IF(I7="","",IF(ISNUMBER(AQ7),AQ7,AD7)) | AS7: =IF(I7="","",IF(Parametreler!$C$7="Evet","Kural A - Hemen Ödeme (Stok Mutabakatlı)","Kural B - Nakliye/Montaj Sonrası Ödeme"))
AJ8: =IF(I8="","",I8&"|"&R8) | AK8: =IF(I8="","",I8&"|"&R8&"|"&O8) | AL8: =IF(I8="","",IF(ISNA(MATCH(O8,Kampanyalar!$A$2:$A$400,0)),"Hayır - Kampanyalar'da Yok","Evet")) | AM8: =IF(I8="","",IFERROR(INDEX(Kampanyalar!$E$2:$E$400,MATCH(O8,Kampanyalar!$A$2:$A$400,0)),"")) | AN8: =IF(I8="","",IFERROR(INDEX(Kampanyalar!$F$2:$F$400,MATCH(O8,Kampanyalar!$A$2:$A$400,0)),"")) | AO8: =IF(I8="","",IFERROR(INDEX(Kampanyalar!$G$2:$G$400,MATCH(O8,Kampanyalar!$A$2:$A$400,0)),"")) | AP8: =IF(OR(I8="",AM8="",AN8=""),"",IF(AND(H8>=AM8,H8<=AN8),"Evet","HAYIR - Tarih Dışı")) | AQ8: =IF(I8="","",IFERROR(INDEX(Kampanyalar!$H$2:$H$400,MATCH(O8,Kampanyalar!$A$2:$A$400,0)),"")) | AR8: =IF(I8="","",IF(ISNUMBER(AQ8),AQ8,AD8)) | AS8: =IF(I8="","",IF(Parametreler!$C$7="Evet","Kural A - Hemen Ödeme (Stok Mutabakatlı)","Kural B - Nakliye/Montaj Sonrası Ödeme"))
AJ9: =IF(I9="","",I9&"|"&R9) | AK9: =IF(I9="","",I9&"|"&R9&"|"&O9) | AL9: =IF(I9="","",IF(ISNA(MATCH(O9,Kampanyalar!$A$2:$A$400,0)),"Hayır - Kampanyalar'da Yok","Evet")) | AM9: =IF(I9="","",IFERROR(INDEX(Kampanyalar!$E$2:$E$400,MATCH(O9,Kampanyalar!$A$2:$A$400,0)),"")) | AN9: =IF(I9="","",IFERROR(INDEX(Kampanyalar!$F$2:$F$400,MATCH(O9,Kampanyalar!$A$2:$A$400,0)),"")) | AO9: =IF(I9="","",IFERROR(INDEX(Kampanyalar!$G$2:$G$400,MATCH(O9,Kampanyalar!$A$2:$A$400,0)),"")) | AP9: =IF(OR(I9="",AM9="",AN9=""),"",IF(AND(H9>=AM9,H9<=AN9),"Evet","HAYIR - Tarih Dışı")) | AQ9: =IF(I9="","",IFERROR(INDEX(Kampanyalar!$H$2:$H$400,MATCH(O9,Kampanyalar!$A$2:$A$400,0)),"")) | AR9: =IF(I9="","",IF(ISNUMBER(AQ9),AQ9,AD9)) | AS9: =IF(I9="","",IF(Parametreler!$C$7="Evet","Kural A - Hemen Ödeme (Stok Mutabakatlı)","Kural B - Nakliye/Montaj Sonrası Ödeme"))
AJ10: =IF(I10="","",I10&"|"&R10) | AK10: =IF(I10="","",I10&"|"&R10&"|"&O10) | AL10: =IF(I10="","",IF(ISNA(MATCH(O10,Kampanyalar!$A$2:$A$400,0)),"Hayır - Kampanyalar'da Yok","Evet")) | AM10: =IF(I10="","",IFERROR(INDEX(Kampanyalar!$E$2:$E$400,MATCH(O10,Kampanyalar!$A$2:$A$400,0)),"")) | AN10: =IF(I10="","",IFERROR(INDEX(Kampanyalar!$F$2:$F$400,MATCH(O10,Kampanyalar!$A$2:$A$400,0)),"")) | AO10: =IF(I10="","",IFERROR(INDEX(Kampanyalar!$G$2:$G$400,MATCH(O10,Kampanyalar!$A$2:$A$400,0)),"")) | AP10: =IF(OR(I10="",AM10="",AN10=""),"",IF(AND(H10>=AM10,H10<=AN10),"Evet","HAYIR - Tarih Dışı")) | AQ10: =IF(I10="","",IFERROR(INDEX(Kampanyalar!$H$2:$H$400,MATCH(O10,Kampanyalar!$A$2:$A$400,0)),"")) | AR10: =IF(I10="","",IF(ISNUMBER(AQ10),AQ10,AD10)) | AS10: =IF(I10="","",IF(Parametreler!$C$7="Evet","Kural A - Hemen Ödeme (Stok Mutabakatlı)","Kural B - Nakliye/Montaj Sonrası Ödeme"))
AJ11: =IF(I11="","",I11&"|"&R11) | AK11: =IF(I11="","",I11&"|"&R11&"|"&O11) | AL11: =IF(I11="","",IF(ISNA(MATCH(O11,Kampanyalar!$A$2:$A$400,0)),"Hayır - Kampanyalar'da Yok","Evet")) | AM11: =IF(I11="","",IFERROR(INDEX(Kampanyalar!$E$2:$E$400,MATCH(O11,Kampanyalar!$A$2:$A$400,0)),"")) | AN11: =IF(I11="","",IFERROR(INDEX(Kampanyalar!$F$2:$F$400,MATCH(O11,Kampanyalar!$A$2:$A$400,0)),"")) | AO11: =IF(I11="","",IFERROR(INDEX(Kampanyalar!$G$2:$G$400,MATCH(O11,Kampanyalar!$A$2:$A$400,0)),"")) | AP11: =IF(OR(I11="",AM11="",AN11=""),"",IF(AND(H11>=AM11,H11<=AN11),"Evet","HAYIR - Tarih Dışı")) | AQ11: =IF(I11="","",IFERROR(INDEX(Kampanyalar!$H$2:$H$400,MATCH(O11,Kampanyalar!$A$2:$A$400,0)),"")) | AR11: =IF(I11="","",IF(ISNUMBER(AQ11),AQ11,AD11)) | AS11: =IF(I11="","",IF(Parametreler!$C$7="Evet","Kural A - Hemen Ödeme (Stok Mutabakatlı)","Kural B - Nakliye/Montaj Sonrası Ödeme"))
AJ12: =IF(I12="","",I12&"|"&R12) | AK12: =IF(I12="","",I12&"|"&R12&"|"&O12) | AL12: =IF(I12="","",IF(ISNA(MATCH(O12,Kampanyalar!$A$2:$A$400,0)),"Hayır - Kampanyalar'da Yok","Evet")) | AM12: =IF(I12="","",IFERROR(INDEX(Kampanyalar!$E$2:$E$400,MATCH(O12,Kampanyalar!$A$2:$A$400,0)),"")) | AN12: =IF(I12="","",IFERROR(INDEX(Kampanyalar!$F$2:$F$400,MATCH(O12,Kampanyalar!$A$2:$A$400,0)),"")) | AO12: =IF(I12="","",IFERROR(INDEX(Kampanyalar!$G$2:$G$400,MATCH(O12,Kampanyalar!$A$2:$A$400,0)),"")) | AP12: =IF(OR(I12="",AM12="",AN12=""),"",IF(AND(H12>=AM12,H12<=AN12),"Evet","HAYIR - Tarih Dışı")) | AQ12: =IF(I12="","",IFERROR(INDEX(Kampanyalar!$H$2:$H$400,MATCH(O12,Kampanyalar!$A$2:$A$400,0)),"")) | AR12: =IF(I12="","",IF(ISNUMBER(AQ12),AQ12,AD12)) | AS12: =IF(I12="","",IF(Parametreler!$C$7="Evet","Kural A - Hemen Ödeme (Stok Mutabakatlı)","Kural B - Nakliye/Montaj Sonrası Ödeme"))
AJ13: =IF(I13="","",I13&"|"&R13) | AK13: =IF(I13="","",I13&"|"&R13&"|"&O13) | AL13: =IF(I13="","",IF(ISNA(MATCH(O13,Kampanyalar!$A$2:$A$400,0)),"Hayır - Kampanyalar'da Yok","Evet")) | AM13: =IF(I13="","",IFERROR(INDEX(Kampanyalar!$E$2:$E$400,MATCH(O13,Kampanyalar!$A$2:$A$400,0)),"")) | AN13: =IF(I13="","",IFERROR(INDEX(Kampanyalar!$F$2:$F$400,MATCH(O13,Kampanyalar!$A$2:$A$400,0)),"")) | AO13: =IF(I13="","",IFERROR(INDEX(Kampanyalar!$G$2:$G$400,MATCH(O13,Kampanyalar!$A$2:$A$400,0)),"")) | AP13: =IF(OR(I13="",AM13="",AN13=""),"",IF(AND(H13>=AM13,H13<=AN13),"Evet","HAYIR - Tarih Dışı")) | AQ13: =IF(I13="","",IFERROR(INDEX(Kampanyalar!$H$2:$H$400,MATCH(O13,Kampanyalar!$A$2:$A$400,0)),"")) | AR13: =IF(I13="","",IF(ISNUMBER(AQ13),AQ13,AD13)) | AS13: =IF(I13="","",IF(Parametreler!$C$7="Evet","Kural A - Hemen Ödeme (Stok Mutabakatlı)","Kural B - Nakliye/Montaj Sonrası Ödeme"))
AJ14: =IF(I14="","",I14&"|"&R14) | AK14: =IF(I14="","",I14&"|"&R14&"|"&O14) | AL14: =IF(I14="","",IF(ISNA(MATCH(O14,Kampanyalar!$A$2:$A$400,0)),"Hayır - Kampanyalar'da Yok","Evet")) | AM14: =IF(I14="","",IFERROR(INDEX(Kampanyalar!$E$2:$E$400,MATCH(O14,Kampanyalar!$A$2:$A$400,0)),"")) | AN14: =IF(I14="","",IFERROR(INDEX(Kampanyalar!$F$2:$F$400,MATCH(O14,Kampanyalar!$A$2:$A$400,0)),"")) | AO14: =IF(I14="","",IFERROR(INDEX(Kampanyalar!$G$2:$G$400,MATCH(O14,Kampanyalar!$A$2:$A$400,0)),"")) | AP14: =IF(OR(I14="",AM14="",AN14=""),"",IF(AND(H14>=AM14,H14<=AN14),"Evet","HAYIR - Tarih Dışı")) | AQ14: =IF(I14="","",IFERROR(INDEX(Kampanyalar!$H$2:$H$400,MATCH(O14,Kampanyalar!$A$2:$A$400,0)),"")) | AR14: =IF(I14="","",IF(ISNUMBER(AQ14),AQ14,AD14)) | AS14: =IF(I14="","",IF(Parametreler!$C$7="Evet","Kural A - Hemen Ödeme (Stok Mutabakatlı)","Kural B - Nakliye/Montaj Sonrası Ödeme"))
... AJ1002: =IF(I1002="","",I1002&"|"&R1002) | AK1002: =IF(I1002="","",I1002&"|"&R1002&"|"&O1002) | AL1002: =IF(I1002="","",IF(ISNA(MATCH(O1002,Kampanyalar!$A$2:$A$400,0)),"Hayır - Kampanyalar'da Yok","Evet")) | AM1002: =IF(I1002="","",IFERROR(INDEX(Kampanyalar!$E$2:$E$400,MATCH(O1002,Kampanyalar!$A$2:$A$400,0)),"")) | AN1002: =IF(I1002="","",IFERROR(INDEX(Kampanyalar!$F$2:$F$400,MATCH(O1002,Kampanyalar!$A$2:$A$400,0)),"")) | AO1002: =IF(I1002="","",IFERROR(INDEX(Kampanyalar!$G$2:$G$400,MATCH(O1002,Kampanyalar!$A$2:$A$400,0)),"")) | AP1002: =IF(OR(I1002="",AM1002="",AN1002=""),"",IF(AND(H1002>=AM1002,H1002<=AN1002),"Evet","HAYIR - Tarih Dışı")) | AQ1002: =IF(I1002="","",IFERROR(INDEX(Kampanyalar!$H$2:$H$400,MATCH(O1002,Kampanyalar!$A$2:$A$400,0)),"")) | AR1002: =IF(I1002="","",IF(ISNUMBER(AQ1002),AQ1002,AD1002)) | AS1002: =IF(I1002="","",IF(Parametreler!$C$7="Evet","Kural A - Hemen Ödeme (Stok Mutabakatlı)","Kural B - Nakliye/Montaj Sonrası Ödeme"))

Sheet E2E Nakliye Montaj
A1: MerkezKodu | B1: BayiKodu | C1: UrunCikisDepoKodu | D1: BayiUnvani | E1: SiparisNo | F1: DivaSiparisFaturaNo | G1: DivaFaturaNo | H1: E2ESiparisNo | I1: SiparisTarihi | J1: SiparisTuru | K1: SiparisKanali | L1: TuketiciAdi | M1: TuketiciSoyadi | N1: TuketiciTelefon | O1: TeslimEdilecekKisiEmail | P1: UrunKodu | Q1: UrunAdi | R1: UrunTipi | S1: TeslimatFisNo | T1: TeslimatDurum | U1: IadeDurum | V1: TeslimatAdresBilgisi | W1: TeslimatTuketiciIl | X1: TeslimatTuketiciIlce | Y1: TeslimatIstenilenTarih | Z1: TeslimatRandevuSaati | AA1: MontajFisNo | AB1: MontajDurum | AC1: MontajIstenilenilenTarih | AD1: MontajRandevuSaati | AE1: SatisTipi | AF1: TeslimatTipi | AG1: Tasiyici | AH1: DepoYeri | AI1: IrsaliyeTarihi | AJ1: IrsaliyeNo | AK1: Platform | AL1: PlatformName | AM1: Eşleştirme Anahtarı | AN1: Sipariş Tarihi (Tarih) | AO1: Teslimat İstenilen Tarih (Tarih) | AP1: Montaj İstenilen Tarih (Tarih) | AQ1: İrsaliye Tarih Metni (yardımcı) | AR1: İrsaliye Tarihi (Tarih) | AS1: Nakliye İzlenebilir mi | AT1: Nakliye Tamamlandı mı | AU1: Montaj Tamamlandı mı | AV1: Hakediş Tetikleyici Tarih
A2: 7000129546 | B2: 7000129546 | C2: 7000129546 | D2: MUSTAFA DEMIREL | E2: TR01-20764369 | F2: 2600000650 | G2: 2600000650 | H2: 5371889 | I2: 24-08-2026 | J2: Offline | K2: DIVA | L2: ÖRNEK | M2: MÜŞTERİ | N2: 5xxxxxxxxx | P2: SMS4IKW62T | Q2: Solo bulaşık makinesi | R2: LDA | T2: Siparişiniz Teslim Edildi | U2: - | V2: Örnek adres | W2: ANTALYA | X2: ALANYA | Y2: 24-08-2026 | AA2: 158360746 | AB2: Siparişinizin Montajı Yapıldı | AC2: 29-08-2026 | AD2: Tüm Gün | AE2: Hemen Teslim Satış | AF2: Mağaza Depodan Tüketiciye | AG2: Servis | AH2: Magaza Depo | AI2: 8/24/2026 6:24:05 PM | AJ2: MDI2026000000099 | AK2: 1354 | AL2: Antalya Platform
AM3: =IF(G3="","",G3&"|"&P3) | AN3: =IF(I3="","",IFERROR(DATE(VALUE(RIGHT(I3,4)),VALUE(MID(I3,4,2)),VALUE(LEFT(I3,2))),"")) | AO3: =IF(Y3="","",IFERROR(DATE(VALUE(RIGHT(Y3,4)),VALUE(MID(Y3,4,2)),VALUE(LEFT(Y3,2))),"")) | AP3: =IF(AC3="","",IFERROR(DATE(VALUE(RIGHT(AC3,4)),VALUE(MID(AC3,4,2)),VALUE(LEFT(AC3,2))),"")) | AQ3: =IF(AI3="","",TRIM(LEFT(AI3,FIND(" ",AI3&" ")-1))) | AR3: =IF(AQ3="","",IFERROR(DATE(VALUE(MID(AQ3,FIND("/",AQ3,FIND("/",AQ3)+1)+1,4)),VALUE(LEFT(AQ3,FIND("/",AQ3)-1)),VALUE(MID(AQ3,FIND("/",AQ3)+1,FIND("/",AQ3,FIND("/",AQ3)+1)-FIND("/",AQ3)-1))),"")) | AS3: =IF(G3="","",IF(AND(AG3<>"",AG3<>"Bayi Aracı"),"Evet","Hayır")) | AT3: =IF(G3="","",IF(AND(AS3="Evet",T3="Siparişiniz Teslim Edildi"),"Evet","Hayır")) | AU3: =IF(G3="","",IF(AB3="Siparişinizin Montajı Yapıldı","Evet","Hayır")) | AV3: =IF(G3="","",IF(AT3="Evet",AR3,IF(AU3="Evet",AP3,"")))
AM4: =IF(G4="","",G4&"|"&P4) | AN4: =IF(I4="","",IFERROR(DATE(VALUE(RIGHT(I4,4)),VALUE(MID(I4,4,2)),VALUE(LEFT(I4,2))),"")) | AO4: =IF(Y4="","",IFERROR(DATE(VALUE(RIGHT(Y4,4)),VALUE(MID(Y4,4,2)),VALUE(LEFT(Y4,2))),"")) | AP4: =IF(AC4="","",IFERROR(DATE(VALUE(RIGHT(AC4,4)),VALUE(MID(AC4,4,2)),VALUE(LEFT(AC4,2))),"")) | AQ4: =IF(AI4="","",TRIM(LEFT(AI4,FIND(" ",AI4&" ")-1))) | AR4: =IF(AQ4="","",IFERROR(DATE(VALUE(MID(AQ4,FIND("/",AQ4,FIND("/",AQ4)+1)+1,4)),VALUE(LEFT(AQ4,FIND("/",AQ4)-1)),VALUE(MID(AQ4,FIND("/",AQ4)+1,FIND("/",AQ4,FIND("/",AQ4)+1)-FIND("/",AQ4)-1))),"")) | AS4: =IF(G4="","",IF(AND(AG4<>"",AG4<>"Bayi Aracı"),"Evet","Hayır")) | AT4: =IF(G4="","",IF(AND(AS4="Evet",T4="Siparişiniz Teslim Edildi"),"Evet","Hayır")) | AU4: =IF(G4="","",IF(AB4="Siparişinizin Montajı Yapıldı","Evet","Hayır")) | AV4: =IF(G4="","",IF(AT4="Evet",AR4,IF(AU4="Evet",AP4,"")))
AM5: =IF(G5="","",G5&"|"&P5) | AN5: =IF(I5="","",IFERROR(DATE(VALUE(RIGHT(I5,4)),VALUE(MID(I5,4,2)),VALUE(LEFT(I5,2))),"")) | AO5: =IF(Y5="","",IFERROR(DATE(VALUE(RIGHT(Y5,4)),VALUE(MID(Y5,4,2)),VALUE(LEFT(Y5,2))),"")) | AP5: =IF(AC5="","",IFERROR(DATE(VALUE(RIGHT(AC5,4)),VALUE(MID(AC5,4,2)),VALUE(LEFT(AC5,2))),"")) | AQ5: =IF(AI5="","",TRIM(LEFT(AI5,FIND(" ",AI5&" ")-1))) | AR5: =IF(AQ5="","",IFERROR(DATE(VALUE(MID(AQ5,FIND("/",AQ5,FIND("/",AQ5)+1)+1,4)),VALUE(LEFT(AQ5,FIND("/",AQ5)-1)),VALUE(MID(AQ5,FIND("/",AQ5)+1,FIND("/",AQ5,FIND("/",AQ5)+1)-FIND("/",AQ5)-1))),"")) | AS5: =IF(G5="","",IF(AND(AG5<>"",AG5<>"Bayi Aracı"),"Evet","Hayır")) | AT5: =IF(G5="","",IF(AND(AS5="Evet",T5="Siparişiniz Teslim Edildi"),"Evet","Hayır")) | AU5: =IF(G5="","",IF(AB5="Siparişinizin Montajı Yapıldı","Evet","Hayır")) | AV5: =IF(G5="","",IF(AT5="Evet",AR5,IF(AU5="Evet",AP5,"")))
AM6: =IF(G6="","",G6&"|"&P6) | AN6: =IF(I6="","",IFERROR(DATE(VALUE(RIGHT(I6,4)),VALUE(MID(I6,4,2)),VALUE(LEFT(I6,2))),"")) | AO6: =IF(Y6="","",IFERROR(DATE(VALUE(RIGHT(Y6,4)),VALUE(MID(Y6,4,2)),VALUE(LEFT(Y6,2))),"")) | AP6: =IF(AC6="","",IFERROR(DATE(VALUE(RIGHT(AC6,4)),VALUE(MID(AC6,4,2)),VALUE(LEFT(AC6,2))),"")) | AQ6: =IF(AI6="","",TRIM(LEFT(AI6,FIND(" ",AI6&" ")-1))) | AR6: =IF(AQ6="","",IFERROR(DATE(VALUE(MID(AQ6,FIND("/",AQ6,FIND("/",AQ6)+1)+1,4)),VALUE(LEFT(AQ6,FIND("/",AQ6)-1)),VALUE(MID(AQ6,FIND("/",AQ6)+1,FIND("/",AQ6,FIND("/",AQ6)+1)-FIND("/",AQ6)-1))),"")) | AS6: =IF(G6="","",IF(AND(AG6<>"",AG6<>"Bayi Aracı"),"Evet","Hayır")) | AT6: =IF(G6="","",IF(AND(AS6="Evet",T6="Siparişiniz Teslim Edildi"),"Evet","Hayır")) | AU6: =IF(G6="","",IF(AB6="Siparişinizin Montajı Yapıldı","Evet","Hayır")) | AV6: =IF(G6="","",IF(AT6="Evet",AR6,IF(AU6="Evet",AP6,"")))
AM7: =IF(G7="","",G7&"|"&P7) | AN7: =IF(I7="","",IFERROR(DATE(VALUE(RIGHT(I7,4)),VALUE(MID(I7,4,2)),VALUE(LEFT(I7,2))),"")) | AO7: =IF(Y7="","",IFERROR(DATE(VALUE(RIGHT(Y7,4)),VALUE(MID(Y7,4,2)),VALUE(LEFT(Y7,2))),"")) | AP7: =IF(AC7="","",IFERROR(DATE(VALUE(RIGHT(AC7,4)),VALUE(MID(AC7,4,2)),VALUE(LEFT(AC7,2))),"")) | AQ7: =IF(AI7="","",TRIM(LEFT(AI7,FIND(" ",AI7&" ")-1))) | AR7: =IF(AQ7="","",IFERROR(DATE(VALUE(MID(AQ7,FIND("/",AQ7,FIND("/",AQ7)+1)+1,4)),VALUE(LEFT(AQ7,FIND("/",AQ7)-1)),VALUE(MID(AQ7,FIND("/",AQ7)+1,FIND("/",AQ7,FIND("/",AQ7)+1)-FIND("/",AQ7)-1))),"")) | AS7: =IF(G7="","",IF(AND(AG7<>"",AG7<>"Bayi Aracı"),"Evet","Hayır")) | AT7: =IF(G7="","",IF(AND(AS7="Evet",T7="Siparişiniz Teslim Edildi"),"Evet","Hayır")) | AU7: =IF(G7="","",IF(AB7="Siparişinizin Montajı Yapıldı","Evet","Hayır")) | AV7: =IF(G7="","",IF(AT7="Evet",AR7,IF(AU7="Evet",AP7,"")))
AM8: =IF(G8="","",G8&"|"&P8) | AN8: =IF(I8="","",IFERROR(DATE(VALUE(RIGHT(I8,4)),VALUE(MID(I8,4,2)),VALUE(LEFT(I8,2))),"")) | AO8: =IF(Y8="","",IFERROR(DATE(VALUE(RIGHT(Y8,4)),VALUE(MID(Y8,4,2)),VALUE(LEFT(Y8,2))),"")) | AP8: =IF(AC8="","",IFERROR(DATE(VALUE(RIGHT(AC8,4)),VALUE(MID(AC8,4,2)),VALUE(LEFT(AC8,2))),"")) | AQ8: =IF(AI8="","",TRIM(LEFT(AI8,FIND(" ",AI8&" ")-1))) | AR8: =IF(AQ8="","",IFERROR(DATE(VALUE(MID(AQ8,FIND("/",AQ8,FIND("/",AQ8)+1)+1,4)),VALUE(LEFT(AQ8,FIND("/",AQ8)-1)),VALUE(MID(AQ8,FIND("/",AQ8)+1,FIND("/",AQ8,FIND("/",AQ8)+1)-FIND("/",AQ8)-1))),"")) | AS8: =IF(G8="","",IF(AND(AG8<>"",AG8<>"Bayi Aracı"),"Evet","Hayır")) | AT8: =IF(G8="","",IF(AND(AS8="Evet",T8="Siparişiniz Teslim Edildi"),"Evet","Hayır")) | AU8: =IF(G8="","",IF(AB8="Siparişinizin Montajı Yapıldı","Evet","Hayır")) | AV8: =IF(G8="","",IF(AT8="Evet",AR8,IF(AU8="Evet",AP8,"")))
AM9: =IF(G9="","",G9&"|"&P9) | AN9: =IF(I9="","",IFERROR(DATE(VALUE(RIGHT(I9,4)),VALUE(MID(I9,4,2)),VALUE(LEFT(I9,2))),"")) | AO9: =IF(Y9="","",IFERROR(DATE(VALUE(RIGHT(Y9,4)),VALUE(MID(Y9,4,2)),VALUE(LEFT(Y9,2))),"")) | AP9: =IF(AC9="","",IFERROR(DATE(VALUE(RIGHT(AC9,4)),VALUE(MID(AC9,4,2)),VALUE(LEFT(AC9,2))),"")) | AQ9: =IF(AI9="","",TRIM(LEFT(AI9,FIND(" ",AI9&" ")-1))) | AR9: =IF(AQ9="","",IFERROR(DATE(VALUE(MID(AQ9,FIND("/",AQ9,FIND("/",AQ9)+1)+1,4)),VALUE(LEFT(AQ9,FIND("/",AQ9)-1)),VALUE(MID(AQ9,FIND("/",AQ9)+1,FIND("/",AQ9,FIND("/",AQ9)+1)-FIND("/",AQ9)-1))),"")) | AS9: =IF(G9="","",IF(AND(AG9<>"",AG9<>"Bayi Aracı"),"Evet","Hayır")) | AT9: =IF(G9="","",IF(AND(AS9="Evet",T9="Siparişiniz Teslim Edildi"),"Evet","Hayır")) | AU9: =IF(G9="","",IF(AB9="Siparişinizin Montajı Yapıldı","Evet","Hayır")) | AV9: =IF(G9="","",IF(AT9="Evet",AR9,IF(AU9="Evet",AP9,"")))
AM10: =IF(G10="","",G10&"|"&P10) | AN10: =IF(I10="","",IFERROR(DATE(VALUE(RIGHT(I10,4)),VALUE(MID(I10,4,2)),VALUE(LEFT(I10,2))),"")) | AO10: =IF(Y10="","",IFERROR(DATE(VALUE(RIGHT(Y10,4)),VALUE(MID(Y10,4,2)),VALUE(LEFT(Y10,2))),"")) | AP10: =IF(AC10="","",IFERROR(DATE(VALUE(RIGHT(AC10,4)),VALUE(MID(AC10,4,2)),VALUE(LEFT(AC10,2))),"")) | AQ10: =IF(AI10="","",TRIM(LEFT(AI10,FIND(" ",AI10&" ")-1))) | AR10: =IF(AQ10="","",IFERROR(DATE(VALUE(MID(AQ10,FIND("/",AQ10,FIND("/",AQ10)+1)+1,4)),VALUE(LEFT(AQ10,FIND("/",AQ10)-1)),VALUE(MID(AQ10,FIND("/",AQ10)+1,FIND("/",AQ10,FIND("/",AQ10)+1)-FIND("/",AQ10)-1))),"")) | AS10: =IF(G10="","",IF(AND(AG10<>"",AG10<>"Bayi Aracı"),"Evet","Hayır")) | AT10: =IF(G10="","",IF(AND(AS10="Evet",T10="Siparişiniz Teslim Edildi"),"Evet","Hayır")) | AU10: =IF(G10="","",IF(AB10="Siparişinizin Montajı Yapıldı","Evet","Hayır")) | AV10: =IF(G10="","",IF(AT10="Evet",AR10,IF(AU10="Evet",AP10,"")))
AM11: =IF(G11="","",G11&"|"&P11) | AN11: =IF(I11="","",IFERROR(DATE(VALUE(RIGHT(I11,4)),VALUE(MID(I11,4,2)),VALUE(LEFT(I11,2))),"")) | AO11: =IF(Y11="","",IFERROR(DATE(VALUE(RIGHT(Y11,4)),VALUE(MID(Y11,4,2)),VALUE(LEFT(Y11,2))),"")) | AP11: =IF(AC11="","",IFERROR(DATE(VALUE(RIGHT(AC11,4)),VALUE(MID(AC11,4,2)),VALUE(LEFT(AC11,2))),"")) | AQ11: =IF(AI11="","",TRIM(LEFT(AI11,FIND(" ",AI11&" ")-1))) | AR11: =IF(AQ11="","",IFERROR(DATE(VALUE(MID(AQ11,FIND("/",AQ11,FIND("/",AQ11)+1)+1,4)),VALUE(LEFT(AQ11,FIND("/",AQ11)-1)),VALUE(MID(AQ11,FIND("/",AQ11)+1,FIND("/",AQ11,FIND("/",AQ11)+1)-FIND("/",AQ11)-1))),"")) | AS11: =IF(G11="","",IF(AND(AG11<>"",AG11<>"Bayi Aracı"),"Evet","Hayır")) | AT11: =IF(G11="","",IF(AND(AS11="Evet",T11="Siparişiniz Teslim Edildi"),"Evet","Hayır")) | AU11: =IF(G11="","",IF(AB11="Siparişinizin Montajı Yapıldı","Evet","Hayır")) | AV11: =IF(G11="","",IF(AT11="Evet",AR11,IF(AU11="Evet",AP11,"")))
AM12: =IF(G12="","",G12&"|"&P12) | AN12: =IF(I12="","",IFERROR(DATE(VALUE(RIGHT(I12,4)),VALUE(MID(I12,4,2)),VALUE(LEFT(I12,2))),"")) | AO12: =IF(Y12="","",IFERROR(DATE(VALUE(RIGHT(Y12,4)),VALUE(MID(Y12,4,2)),VALUE(LEFT(Y12,2))),"")) | AP12: =IF(AC12="","",IFERROR(DATE(VALUE(RIGHT(AC12,4)),VALUE(MID(AC12,4,2)),VALUE(LEFT(AC12,2))),"")) | AQ12: =IF(AI12="","",TRIM(LEFT(AI12,FIND(" ",AI12&" ")-1))) | AR12: =IF(AQ12="","",IFERROR(DATE(VALUE(MID(AQ12,FIND("/",AQ12,FIND("/",AQ12)+1)+1,4)),VALUE(LEFT(AQ12,FIND("/",AQ12)-1)),VALUE(MID(AQ12,FIND("/",AQ12)+1,FIND("/",AQ12,FIND("/",AQ12)+1)-FIND("/",AQ12)-1))),"")) | AS12: =IF(G12="","",IF(AND(AG12<>"",AG12<>"Bayi Aracı"),"Evet","Hayır")) | AT12: =IF(G12="","",IF(AND(AS12="Evet",T12="Siparişiniz Teslim Edildi"),"Evet","Hayır")) | AU12: =IF(G12="","",IF(AB12="Siparişinizin Montajı Yapıldı","Evet","Hayır")) | AV12: =IF(G12="","",IF(AT12="Evet",AR12,IF(AU12="Evet",AP12,"")))
AM13: =IF(G13="","",G13&"|"&P13) | AN13: =IF(I13="","",IFERROR(DATE(VALUE(RIGHT(I13,4)),VALUE(MID(I13,4,2)),VALUE(LEFT(I13,2))),"")) | AO13: =IF(Y13="","",IFERROR(DATE(VALUE(RIGHT(Y13,4)),VALUE(MID(Y13,4,2)),VALUE(LEFT(Y13,2))),"")) | AP13: =IF(AC13="","",IFERROR(DATE(VALUE(RIGHT(AC13,4)),VALUE(MID(AC13,4,2)),VALUE(LEFT(AC13,2))),"")) | AQ13: =IF(AI13="","",TRIM(LEFT(AI13,FIND(" ",AI13&" ")-1))) | AR13: =IF(AQ13="","",IFERROR(DATE(VALUE(MID(AQ13,FIND("/",AQ13,FIND("/",AQ13)+1)+1,4)),VALUE(LEFT(AQ13,FIND("/",AQ13)-1)),VALUE(MID(AQ13,FIND("/",AQ13)+1,FIND("/",AQ13,FIND("/",AQ13)+1)-FIND("/",AQ13)-1))),"")) | AS13: =IF(G13="","",IF(AND(AG13<>"",AG13<>"Bayi Aracı"),"Evet","Hayır")) | AT13: =IF(G13="","",IF(AND(AS13="Evet",T13="Siparişiniz Teslim Edildi"),"Evet","Hayır")) | AU13: =IF(G13="","",IF(AB13="Siparişinizin Montajı Yapıldı","Evet","Hayır")) | AV13: =IF(G13="","",IF(AT13="Evet",AR13,IF(AU13="Evet",AP13,"")))
AM14: =IF(G14="","",G14&"|"&P14) | AN14: =IF(I14="","",IFERROR(DATE(VALUE(RIGHT(I14,4)),VALUE(MID(I14,4,2)),VALUE(LEFT(I14,2))),"")) | AO14: =IF(Y14="","",IFERROR(DATE(VALUE(RIGHT(Y14,4)),VALUE(MID(Y14,4,2)),VALUE(LEFT(Y14,2))),"")) | AP14: =IF(AC14="","",IFERROR(DATE(VALUE(RIGHT(AC14,4)),VALUE(MID(AC14,4,2)),VALUE(LEFT(AC14,2))),"")) | AQ14: =IF(AI14="","",TRIM(LEFT(AI14,FIND(" ",AI14&" ")-1))) | AR14: =IF(AQ14="","",IFERROR(DATE(VALUE(MID(AQ14,FIND("/",AQ14,FIND("/",AQ14)+1)+1,4)),VALUE(LEFT(AQ14,FIND("/",AQ14)-1)),VALUE(MID(AQ14,FIND("/",AQ14)+1,FIND("/",AQ14,FIND("/",AQ14)+1)-FIND("/",AQ14)-1))),"")) | AS14: =IF(G14="","",IF(AND(AG14<>"",AG14<>"Bayi Aracı"),"Evet","Hayır")) | AT14: =IF(G14="","",IF(AND(AS14="Evet",T14="Siparişiniz Teslim Edildi"),"Evet","Hayır")) | AU14: =IF(G14="","",IF(AB14="Siparişinizin Montajı Yapıldı","Evet","Hayır")) | AV14: =IF(G14="","",IF(AT14="Evet",AR14,IF(AU14="Evet",AP14,"")))
... AM1002: =IF(G1002="","",G1002&"|"&P1002) | AN1002: =IF(I1002="","",IFERROR(DATE(VALUE(RIGHT(I1002,4)),VALUE(MID(I1002,4,2)),VALUE(LEFT(I1002,2))),"")) | AO1002: =IF(Y1002="","",IFERROR(DATE(VALUE(RIGHT(Y1002,4)),VALUE(MID(Y1002,4,2)),VALUE(LEFT(Y1002,2))),"")) | AP1002: =IF(AC1002="","",IFERROR(DATE(VALUE(RIGHT(AC1002,4)),VALUE(MID(AC1002,4,2)),VALUE(LEFT(AC1002,2))),"")) | AQ1002: =IF(AI1002="","",TRIM(LEFT(AI1002,FIND(" ",AI1002&" ")-1))) | AR1002: =IF(AQ1002="","",IFERROR(DATE(VALUE(MID(AQ1002,FIND("/",AQ1002,FIND("/",AQ1002)+1)+1,4)),VALUE(LEFT(AQ1002,FIND("/",AQ1002)-1)),VALUE(MID(AQ1002,FIND("/",AQ1002)+1,FIND("/",AQ1002,FIND("/",AQ1002)+1)-FIND("/",AQ1002)-1))),"")) | AS1002: =IF(G1002="","",IF(AND(AG1002<>"",AG1002<>"Bayi Aracı"),"Evet","Hayır")) | AT1002: =IF(G1002="","",IF(AND(AS1002="Evet",T1002="Siparişiniz Teslim Edildi"),"Evet","Hayır")) | AU1002: =IF(G1002="","",IF(AB1002="Siparişinizin Montajı Yapıldı","Evet","Hayır")) | AV1002: =IF(G1002="","",IF(AT1002="Evet",AR1002,IF(AU1002="Evet",AP1002,"")))

Sheet Hakedis Fatura Detay
A1: Satış id | B1: Bölge | C1: Alt Bölge | D1: Rut | E1: Bayi Kodu | F1: Nihai Kod | G1: Bayi Ünvanı | H1: Fatura No | I1: Değişen Fatura No | J1: Ürün Kodu | K1: LPH 2 | L1: LPH 3 | M1: İade Durumu | N1: Satış Tipi | O1: Fatura Tipi | P1: eLogo | Q1: Kime Satış | R1: Ödeme Yöntemi | S1: Diva Yaratma Tarihi | T1: Fatura Tarihi | U1: Montaj Tarihi | V1: Montaj Fiş No | W1: Nakliye Tarihi | X1: Nakliye Kaynağı | Y1: Nakliye Fiş No | Z1: Kampanya Adı 1 | AA1: Kampanya Türü 1 | AB1: Yöntem 1 | AC1: Toplam Tutar 1 | AD1: Prim Fonundan 1 | AE1: Karlılıktan 1 | AF1: Toplam Tutar H 1 | AG1: Eşleştirme Anahtarı (Ürün Düzeyi) | AH1: Eşleştirme Anahtarı (Kampanya Düzeyi) | AI1: Kural (Ödeme Yöntemine Göre) | AJ1: Nakliye Tarihi (Ayrıştırılmış) | AK1: Hakediş Tetikleyici Tarih | AM1: Kaynak: BSH'nin bayiye gönderdiği aylık hakediş detay raporu ("... DETAY" sekmesi). Bir ürün aynı anda birden fazla kampanyaya konu olabildiğinden (ör. tekil + bundle), aynı Fatura No + Ürün Kodu için birden fazla satır olabilir; her satır 'Kampanya Adı 1' ile ayrı bir kampanya uygulamasını temsil eder. Bu yüzden eşleştirme Fatura No + Ürün Kodu + Kampanya Adı üçlüsüyle yapılır.
A2: 7000129546|2600007552 | B2: TRBB | C2: TB3 | D2: 000TRRBB32 | E2: 7000129546 | F2: 7000129546 | G2: ÖRNEK BAYİ ÜNVANI LTD.ŞTİ. | H2: 2600007552 | I2: - | J2: SMS4IKW62T | K2: LDA | L2: Bosch-LDA-BULAŞIK MAKİNESİ | M2: Geçerli | N2: Hemen Teslim | O2: e-Arşiv | P2: 1 | Q2: Tüketici | R2: Mutabakat Yoksa | S2: 30.07.2026 | T2: 30.07.2026 | U2: - | V2: - | W2: 2026-07-31 | X2: e2e | Y2: TR01-20674473 | Z2: Temmuz-Tekil Bulaşık Makinesi Kampanyası-202607 | AA2: Muhtelif Ürünler Fiyat Farkı | AB2: Montaj veya Nakliye | AC2: 3777.92 | AD2: 0 | AE2: 3777.92 | AF2: 3777.92 | AM2: Yüklü veride EN ESKİ hakediş fatura tarihi (otomatik): | AN2: =IFERROR(MINIFS($T$3:$T$1500,$H$3:$H$1500,"<>"),"")
AG3: =IF(H3="","",TEXT(H3,"0")&"|"&J3) | AH3: =IF(H3="","",TEXT(H3,"0")&"|"&J3&"|"&Z3) | AI3: =IF(H3="","",IF(R3="Mutabakat Yoksa","Kural B - Nakliye/Montaj Sonrası Ödeme","Kural A - Hemen Ödeme (Stok Mutabakatlı)")) | AJ3: =IF(OR(W3="",W3="-"),"",IFERROR(DATE(VALUE(LEFT(W3,4)),VALUE(MID(W3,6,2)),VALUE(RIGHT(W3,2))),"")) | AK3: =IF(H3="","",IF(AB3="Diva Fatura",T3,IF(AJ3<>"",AJ3,IF(ISNUMBER(U3),U3,"")))) | AM3: Yüklü veride EN YENİ hakediş fatura tarihi (otomatik): | AN3: =IFERROR(MAXIFS($T$3:$T$1500,$H$3:$H$1500,"<>"),"")
AG4: =IF(H4="","",TEXT(H4,"0")&"|"&J4) | AH4: =IF(H4="","",TEXT(H4,"0")&"|"&J4&"|"&Z4) | AI4: =IF(H4="","",IF(R4="Mutabakat Yoksa","Kural B - Nakliye/Montaj Sonrası Ödeme","Kural A - Hemen Ödeme (Stok Mutabakatlı)")) | AJ4: =IF(OR(W4="",W4="-"),"",IFERROR(DATE(VALUE(LEFT(W4,4)),VALUE(MID(W4,6,2)),VALUE(RIGHT(W4,2))),"")) | AK4: =IF(H4="","",IF(AB4="Diva Fatura",T4,IF(AJ4<>"",AJ4,IF(ISNUMBER(U4),U4,"")))) | AM4: Bu iki tarih, Kontrol sekmesinde 'bu satıştan önceki bir döneme ait hakediş dosyası hiç yüklenmemiş olabilir' uyarısını üretmek için kullanılır. Hakediş verinizi ay ay BİRİKTİREREK (üstüne yapıştırıp SİLMEDEN, altına ekleyerek) yüklerseniz bu uyarı neredeyse hiç çıkmaz.
AG5: =IF(H5="","",TEXT(H5,"0")&"|"&J5) | AH5: =IF(H5="","",TEXT(H5,"0")&"|"&J5&"|"&Z5) | AI5: =IF(H5="","",IF(R5="Mutabakat Yoksa","Kural B - Nakliye/Montaj Sonrası Ödeme","Kural A - Hemen Ödeme (Stok Mutabakatlı)")) | AJ5: =IF(OR(W5="",W5="-"),"",IFERROR(DATE(VALUE(LEFT(W5,4)),VALUE(MID(W5,6,2)),VALUE(RIGHT(W5,2))),"")) | AK5: =IF(H5="","",IF(AB5="Diva Fatura",T5,IF(AJ5<>"",AJ5,IF(ISNUMBER(U5),U5,""))))
AG6: =IF(H6="","",TEXT(H6,"0")&"|"&J6) | AH6: =IF(H6="","",TEXT(H6,"0")&"|"&J6&"|"&Z6) | AI6: =IF(H6="","",IF(R6="Mutabakat Yoksa","Kural B - Nakliye/Montaj Sonrası Ödeme","Kural A - Hemen Ödeme (Stok Mutabakatlı)")) | AJ6: =IF(OR(W6="",W6="-"),"",IFERROR(DATE(VALUE(LEFT(W6,4)),VALUE(MID(W6,6,2)),VALUE(RIGHT(W6,2))),"")) | AK6: =IF(H6="","",IF(AB6="Diva Fatura",T6,IF(AJ6<>"",AJ6,IF(ISNUMBER(U6),U6,""))))
AG7: =IF(H7="","",TEXT(H7,"0")&"|"&J7) | AH7: =IF(H7="","",TEXT(H7,"0")&"|"&J7&"|"&Z7) | AI7: =IF(H7="","",IF(R7="Mutabakat Yoksa","Kural B - Nakliye/Montaj Sonrası Ödeme","Kural A - Hemen Ödeme (Stok Mutabakatlı)")) | AJ7: =IF(OR(W7="",W7="-"),"",IFERROR(DATE(VALUE(LEFT(W7,4)),VALUE(MID(W7,6,2)),VALUE(RIGHT(W7,2))),"")) | AK7: =IF(H7="","",IF(AB7="Diva Fatura",T7,IF(AJ7<>"",AJ7,IF(ISNUMBER(U7),U7,""))))
AG8: =IF(H8="","",TEXT(H8,"0")&"|"&J8) | AH8: =IF(H8="","",TEXT(H8,"0")&"|"&J8&"|"&Z8) | AI8: =IF(H8="","",IF(R8="Mutabakat Yoksa","Kural B - Nakliye/Montaj Sonrası Ödeme","Kural A - Hemen Ödeme (Stok Mutabakatlı)")) | AJ8: =IF(OR(W8="",W8="-"),"",IFERROR(DATE(VALUE(LEFT(W8,4)),VALUE(MID(W8,6,2)),VALUE(RIGHT(W8,2))),"")) | AK8: =IF(H8="","",IF(AB8="Diva Fatura",T8,IF(AJ8<>"",AJ8,IF(ISNUMBER(U8),U8,""))))
AG9: =IF(H9="","",TEXT(H9,"0")&"|"&J9) | AH9: =IF(H9="","",TEXT(H9,"0")&"|"&J9&"|"&Z9) | AI9: =IF(H9="","",IF(R9="Mutabakat Yoksa","Kural B - Nakliye/Montaj Sonrası Ödeme","Kural A - Hemen Ödeme (Stok Mutabakatlı)")) | AJ9: =IF(OR(W9="",W9="-"),"",IFERROR(DATE(VALUE(LEFT(W9,4)),VALUE(MID(W9,6,2)),VALUE(RIGHT(W9,2))),"")) | AK9: =IF(H9="","",IF(AB9="Diva Fatura",T9,IF(AJ9<>"",AJ9,IF(ISNUMBER(U9),U9,""))))
AG10: =IF(H10="","",TEXT(H10,"0")&"|"&J10) | AH10: =IF(H10="","",TEXT(H10,"0")&"|"&J10&"|"&Z10) | AI10: =IF(H10="","",IF(R10="Mutabakat Yoksa","Kural B - Nakliye/Montaj Sonrası Ödeme","Kural A - Hemen Ödeme (Stok Mutabakatlı)")) | AJ10: =IF(OR(W10="",W10="-"),"",IFERROR(DATE(VALUE(LEFT(W10,4)),VALUE(MID(W10,6,2)),VALUE(RIGHT(W10,2))),"")) | AK10: =IF(H10="","",IF(AB10="Diva Fatura",T10,IF(AJ10<>"",AJ10,IF(ISNUMBER(U10),U10,""))))
AG11: =IF(H11="","",TEXT(H11,"0")&"|"&J11) | AH11: =IF(H11="","",TEXT(H11,"0")&"|"&J11&"|"&Z11) | AI11: =IF(H11="","",IF(R11="Mutabakat Yoksa","Kural B - Nakliye/Montaj Sonrası Ödeme","Kural A - Hemen Ödeme (Stok Mutabakatlı)")) | AJ11: =IF(OR(W11="",W11="-"),"",IFERROR(DATE(VALUE(LEFT(W11,4)),VALUE(MID(W11,6,2)),VALUE(RIGHT(W11,2))),"")) | AK11: =IF(H11="","",IF(AB11="Diva Fatura",T11,IF(AJ11<>"",AJ11,IF(ISNUMBER(U11),U11,""))))
AG12: =IF(H12="","",TEXT(H12,"0")&"|"&J12) | AH12: =IF(H12="","",TEXT(H12,"0")&"|"&J12&"|"&Z12) | AI12: =IF(H12="","",IF(R12="Mutabakat Yoksa","Kural B - Nakliye/Montaj Sonrası Ödeme","Kural A - Hemen Ödeme (Stok Mutabakatlı)")) | AJ12: =IF(OR(W12="",W12="-"),"",IFERROR(DATE(VALUE(LEFT(W12,4)),VALUE(MID(W12,6,2)),VALUE(RIGHT(W12,2))),"")) | AK12: =IF(H12="","",IF(AB12="Diva Fatura",T12,IF(AJ12<>"",AJ12,IF(ISNUMBER(U12),U12,""))))
AG13: =IF(H13="","",TEXT(H13,"0")&"|"&J13) | AH13: =IF(H13="","",TEXT(H13,"0")&"|"&J13&"|"&Z13) | AI13: =IF(H13="","",IF(R13="Mutabakat Yoksa","Kural B - Nakliye/Montaj Sonrası Ödeme","Kural A - Hemen Ödeme (Stok Mutabakatlı)")) | AJ13: =IF(OR(W13="",W13="-"),"",IFERROR(DATE(VALUE(LEFT(W13,4)),VALUE(MID(W13,6,2)),VALUE(RIGHT(W13,2))),"")) | AK13: =IF(H13="","",IF(AB13="Diva Fatura",T13,IF(AJ13<>"",AJ13,IF(ISNUMBER(U13),U13,""))))
AG14: =IF(H14="","",TEXT(H14,"0")&"|"&J14) | AH14: =IF(H14="","",TEXT(H14,"0")&"|"&J14&"|"&Z14) | AI14: =IF(H14="","",IF(R14="Mutabakat Yoksa","Kural B - Nakliye/Montaj Sonrası Ödeme","Kural A - Hemen Ödeme (Stok Mutabakatlı)")) | AJ14: =IF(OR(W14="",W14="-"),"",IFERROR(DATE(VALUE(LEFT(W14,4)),VALUE(MID(W14,6,2)),VALUE(RIGHT(W14,2))),"")) | AK14: =IF(H14="","",IF(AB14="Diva Fatura",T14,IF(AJ14<>"",AJ14,IF(ISNUMBER(U14),U14,""))))
AG15: =IF(H15="","",TEXT(H15,"0")&"|"&J15) | AH15: =IF(H15="","",TEXT(H15,"0")&"|"&J15&"|"&Z15) | AI15: =IF(H15="","",IF(R15="Mutabakat Yoksa","Kural B - Nakliye/Montaj Sonrası Ödeme","Kural A - Hemen Ödeme (Stok Mutabakatlı)")) | AJ15: =IF(OR(W15="",W15="-"),"",IFERROR(DATE(VALUE(LEFT(W15,4)),VALUE(MID(W15,6,2)),VALUE(RIGHT(W15,2))),"")) | AK15: =IF(H15="","",IF(AB15="Diva Fatura",T15,IF(AJ15<>"",AJ15,IF(ISNUMBER(U15),U15,""))))
AG16: =IF(H16="","",TEXT(H16,"0")&"|"&J16) | AH16: =IF(H16="","",TEXT(H16,"0")&"|"&J16&"|"&Z16) | AI16: =IF(H16="","",IF(R16="Mutabakat Yoksa","Kural B - Nakliye/Montaj Sonrası Ödeme","Kural A - Hemen Ödeme (Stok Mutabakatlı)")) | AJ16: =IF(OR(W16="",W16="-"),"",IFERROR(DATE(VALUE(LEFT(W16,4)),VALUE(MID(W16,6,2)),VALUE(RIGHT(W16,2))),"")) | AK16: =IF(H16="","",IF(AB16="Diva Fatura",T16,IF(AJ16<>"",AJ16,IF(ISNUMBER(U16),U16,""))))
... AG1500: =IF(H1500="","",TEXT(H1500,"0")&"|"&J1500) | AH1500: =IF(H1500="","",TEXT(H1500,"0")&"|"&J1500&"|"&Z1500) | AI1500: =IF(H1500="","",IF(R1500="Mutabakat Yoksa","Kural B - Nakliye/Montaj Sonrası Ödeme","Kural A - Hemen Ödeme (Stok Mutabakatlı)")) | AJ1500: =IF(OR(W1500="",W1500="-"),"",IFERROR(DATE(VALUE(LEFT(W1500,4)),VALUE(MID(W1500,6,2)),VALUE(RIGHT(W1500,2))),"")) | AK1500: =IF(H1500="","",IF(AB1500="Diva Fatura",T1500,IF(AJ1500<>"",AJ1500,IF(ISNUMBER(U1500),U1500,""))))

Sheet Kontrol
A1: Fatura No | B1: Ürün Kodu | C1: Ad Soyad | D1: Fatura Tarihi | E1: Paket Adı (Kampanya) | F1: Kampanya Bulundu mu | G1: Kampanya Aralığında mı | H1: Hakediş Son Tarihi | I1: Beklenen Hakediş Tutarı | J1: Uygulanacak Kural (Ön Beklenti) | K1: Hakediş Faturasında Bulundu mu | L1: HFD Ödeme Yöntemi | M1: HFD'ye Göre Kural | N1: HFD Yöntem 1 | O1: HFD Hakediş Tetikleyici Tarih | P1: Süre İçinde Tamamlandı mı | Q1: E2E: Nakliye Tamamlandı mı | R1: E2E: Montaj Tamamlandı mı | S1: E2E-HFD Tutarlılığı | T1: Faturada Bulunan Tutar | U1: Tutar Farkı | V1: Tutar Durumu | W1: GENEL DURUM | X1: Veri Kapsamı Uyarısı (eski ay hakedişi olabilir) | Y1: Sorun Raporu Sıra No (yardımcı)
